Workbook

Sheet Question 1
B1: Question 1
B2: financial figures in millions
A3: a) | B3: Develop base case projections of Newmont's income statement for the years 2025-2029. Assume that sales grows by 10% per year, that gross margin (sales minus costs applicable to sales) remains constant at 2024 levels, and all other costs and expenses grow at 5%, with the exception of impairment charges which are expected to be zero. Note that Newmont 2024 results will be released after market close on February 20.
B5: Description | C5: FY 23 | D5: FY24
B6: Period Ended On (MM/DD/YYYY) | C6: 12/31/2023 | D6: 12/31/2024 | F6: Projection | L6: Notes
B7: Reported Date (MM/DD/YYYY) | C7: 02/29/2024 | D7: 02/20/2025 | F7: FY25 | G7: FY26 | H7: FY27 | I7: FY28 | J7: FY29
B8: Sales | C8: 11812 | D8: 18682 | F8: =D8*(1+$K$8) -> 20550.2 | G8: =F8*(1+$K$8) -> 22605.22 | H8: =G8*(1+$K$8) -> 24865.742 | I8: =H8*(1+$K$8) -> 27352.316 | J8: =I8*(1+$K$8) -> 30087.548 | K8: 0.1 | L8: Assume annual growth of 10%
B9: Costs and expenses
B10: Costs applicable to sales | C10: 6699 | D10: 8963 | F10: =($D$10/$D$8)*F8 -> 9859.3 | G10: =($D$10/$D$8)*G8 -> 10845.23 | H10: =($D$10/$D$8)*H8 -> 11929.753 | I10: =($D$10/$D$8)*I8 -> 13122.728 | J10: =($D$10/$D$8)*J8 -> 14435.001 | L10: Assume constant gross margin from 2024
B11: Depreciation and amortization | C11: 2108 | D11: 2576 | F11: =D11*(1+$K$11) -> 2704.8 | G11: =F11*(1+$K$11) -> 2840.04 | H11: =G11*(1+$K$11) -> 2982.042 | I11: =H11*(1+$K$11) -> 3131.1441 | J11: =I11*(1+$K$11) -> 3287.7013 | K11: 0.05 | L11: Assume annual growth of 5%
B12: Reclamation and remediation | C12: 1533 | D12: 328 | F12: =D12*(1+$K$11) -> 344.4 | G12: =F12*(1+$K$11) -> 361.62 | H12: =G12*(1+$K$11) -> 379.701 | I12: =H12*(1+$K$11) -> 398.68605 | J12: =I12*(1+$K$11) -> 418.62035 | L12: Assume annual growth of 5%
B13: Exploration | C13: 265 | D13: 266 | F13: =D13*(1+$K$11) -> 279.3 | G13: =F13*(1+$K$11) -> 293.265 | H13: =G13*(1+$K$11) -> 307.92825 | I13: =H13*(1+$K$11) -> 323.32466 | J13: =I13*(1+$K$11) -> 339.4909 | L13: Assume annual growth of 5%
B14: Advanced projects, research and development | C14: 200 | D14: 197 | F14: =D14*(1+$K$11) -> 206.85 | G14: =F14*(1+$K$11) -> 217.1925 | H14: =G14*(1+$K$11) -> 228.05212 | I14: =H14*(1+$K$11) -> 239.45473 | J14: =I14*(1+$K$11) -> 251.42747 | L14: Assume annual growth of 5%
B15: General and administrative | C15: 299 | D15: 442 | F15: =D15*(1+$K$11) -> 464.1 | G15: =F15*(1+$K$11) -> 487.305 | H15: =G15*(1+$K$11) -> 511.67025 | I15: =H15*(1+$K$11) -> 537.25376 | J15: =I15*(1+$K$11) -> 564.11645 | L15: Assume annual growth of 5%
B16: Care and maintenance | F16: 0 | G16: 0 | H16: 0 | I16: 0 | J16: 0
B17: Loss on assets held for sale | C17: 0 | D17: 1114 | F17: =D17*(1+$K$11) -> 1169.7 | G17: =F17*(1+$K$11) -> 1228.185 | H17: =G17*(1+$K$11) -> 1289.5943 | I17: =H17*(1+$K$11) -> 1354.074 | J17: =I17*(1+$K$11) -> 1421.7777 | L17: Assume annual growth of 5%
B18: Impairment charges | C18: 1891 | D18: 78 | F18: 0 | G18: 0 | H18: 0 | I18: 0 | J18: 0 | L18: Assume zero impairment charges
B19: Other expense, net | C19: 517 | D19: 191 | F19: =D19*(1+$K$11) -> 200.55 | G19: =F19*(1+$K$11) -> 210.5775 | H19: =G19*(1+$K$11) -> 221.10638 | I19: =H19*(1+$K$11) -> 232.16169 | J19: =I19*(1+$K$11) -> 243.76978 | L19: Assume annual growth of 5%
B20: Total costs and expenses | C20: =SUM(C10:C19) -> 13512 | D20: =SUM(D10:D19) -> 14155 | F20: =SUM(F10:F19) -> 15229 | G20: =SUM(G10:G19) -> 16483.415 | H20: =SUM(H10:H19) -> 17849.847 | I20: =SUM(I10:I19) -> 19338.827 | J20: =SUM(J10:J19) -> 20961.905
B22: Operating Income | F22: =F8-F20 -> 5321.2 | G22: =G8-G20 -> 6121.805 | H22: =H8-H20 -> 7015.8948 | I22: =I8-I20 -> 8013.4889 | J22: =J8-J20 -> 9125.6428 | L22: Operating Income
B23: Other income (expense)
B24: Gain on formation of Nevada Gold Mines | C24: 0 | D24: 0 | F24: =($D$24/$D$8)*$F$8 -> 0 | G24: =($D$24/$D$8)*$F$8 -> 0 | H24: =($D$24/$D$8)*$F$8 -> 0 | I24: =($D$24/$D$8)*$F$8 -> 0 | J24: =($D$24/$D$8)*$F$8 -> 0 | L24: Assuming constant value from 2024
B25: Gain on asset and investment sales, net | C25: 0 | D25: 0 | F25: =($D$25/$D$8)*$F$8 -> 0 | G25: =($D$25/$D$8)*$F$8 -> 0 | H25: =($D$25/$D$8)*$F$8 -> 0 | I25: =($D$25/$D$8)*$F$8 -> 0 | J25: =($D$25/$D$8)*$F$8 -> 0
B26: Other income (loss), net | C26: -88 | D26: 425 | F26: =$D$26 -> 425 | G26: =$D$26 -> 425 | H26: =$D$26 -> 425 | I26: =$D$26 -> 425 | J26: =$D$26 -> 425
B27: Interest expense, net of capitalized interest​ | C27: -243 | D27: =-375 -> -375 | F27: =$D$27 -> -375 | G27: =$D$27 -> -375 | H27: =$D$27 -> -375 | I27: =$D$27 -> -375 | J27: =$D$27 -> -375
B28: Total other income (expense) | C28: =SUM(C24:C27) -> -331 | D28: =SUM(D24:D27) -> 50 | F28: =SUM($F$24:$F$27) -> 50 | G28: =SUM($F$24:$F$27) -> 50 | H28: =SUM($F$24:$F$27) -> 50 | I28: =SUM($F$24:$F$27) -> 50 | J28: =SUM($F$24:$F$27) -> 50
B29: Income (loss) before income and mining tax and other items | C29: -2031 | D29: 4577 | F29: =SUM(F22:F27) -> 5371.2 | G29: =SUM(G22:G27) -> 6171.805 | H29: =SUM(H22:H27) -> 7065.8948 | I29: =SUM(I22:I27) -> 8063.4889 | J29: =SUM(J22:J27) -> 9175.6428
B30: Income and mining tax benefit (expense) | C30: -526 | D30: =-1397 -> -1397 | F30: =$D$30 -> -1397 | G30: =$D$30 -> -1397 | H30: =$D$30 -> -1397 | I30: =$D$30 -> -1397 | J30: =$D$30 -> -1397
B31: Equity income (loss) of affiliates | C31: 63 | D31: 133 | F31: =$D$31 -> 133 | G31: =$D$31 -> 133 | H31: =$D$31 -> 133 | I31: =$D$31 -> 133 | J31: =$D$31 -> 133
B32: Net income (loss) from continuing operations | C32: =SUM(C29:C31) -> -2494 | D32: =SUM(D29:D31) -> 3313 | F32: =SUM(F29:F31) -> 4107.2 | G32: =SUM(G29:G31) -> 4907.805 | H32: =SUM(H29:H31) -> 5801.8948 | I32: =SUM(I29:I31) -> 6799.4889 | J32: =SUM(J29:J31) -> 7911.6428
B33: Net income (loss) from discontinued operations | C33: 27 | D33: 68 | F33: =$D$33 -> 68 | G33: =$D$33 -> 68 | H33: =$D$33 -> 68 | I33: =$D$33 -> 68 | J33: =$D$33 -> 68
B34: Net income (loss) | C34: =SUM(C32:C33) -> -2467 | D34: =SUM(D32:D33) -> 3381 | F34: =SUM(F32:F33) -> 4175.2 | G34: =SUM(G32:G33) -> 4975.805 | H34: =SUM(H32:H33) -> 5869.8948 | I34: =SUM(I32:I33) -> 6867.4889 | J34: =SUM(J32:J33) -> 7979.6428
A37: b) | B37: Suppose Newmont faces road closures and access interruptions due to more frequent flooding in its Ahafo South, Tanami & Lihir mines, which leads to output shortages for these three mines. Assume that sales decrease by 6% each year relative to base case for the next 5 years. Using information in the financial and climate disclosures, attempt to construct the change in sales, costs & expenses, operating income and total asset values as a result of this scenario. Justify your expected changes. [NOTE: Assume that operating income equals income before interest and taxes. Assume that the 2024 interest expense stays constant and that the 2024 tax rate stays constant for the next 5 years].
B39: Description | C39: FY 23 | D39: FY24
B40: Period Ended On (MM/DD/YYYY) | C40: 12/31/2023 | D40: 12/31/2024 | F40: Projection
B41: Reported Date (MM/DD/YYYY) | C41: 02/29/2024 | D41: 02/20/2025 | F41: FY25 | G41: FY26 | H41: FY27 | I41: FY28 | J41: FY29
B42: Sales | C42: 11812 | D42: 18682 | F42: =D42*(1-$K$42) -> 17561.08 | G42: =F42*(1-$K$42) -> 16507.415 | H42: =G42*(1-$K$42) -> 15516.97 | I42: =H42*(1-$K$42) -> 14585.952 | J42: =I42*(1-$K$42) -> 13710.795 | K42: 0.06 | L42: Assume decrease by 6% each year relative to base case | M42: This is based on the Climate Disclosure Report from Newmont, stated that the flooding caused decrease in sales revenue due to the distruption in their business operations
B43: Costs and expenses
B44: Costs applicable to sales | C44: 6699 | D44: 8963 | F44: =($D$10/$D$8)*F42 -> 8425.22 | G44: =($D$10/$D$8)*G42 -> 7919.7068 | H44: =($D$10/$D$8)*H42 -> 7444.5244 | I44: =($D$10/$D$8)*I42 -> 6997.8529 | J44: =($D$10/$D$8)*J42 -> 6577.9818 | L44: Assumption constant gross margin from FY2024
B45: Depreciation and amortization | C45: 2108 | D45: 2576 | F45: =D45*(1+$K$11) -> 2704.8 | G45: =F45*(1+$K$11) -> 2840.04 | H45: =G45*(1+$K$11) -> 2982.042 | I45: =H45*(1+$K$11) -> 3131.1441 | J45: =I45*(1+$K$11) -> 3287.7013 | K45: 0.05 | L45: Assume annual growth of 5% | M45: assumption on cost always increase every year even with decrease In sales
...

Sheet Balance Sheet for Q.1B 
A1: Currency | B1: Unit | C1: Description | D1: FY 23
C2: Period Ended On (MM/DD/YYYY) | D2: 12/31/2023
C3: Reported Date (MM/DD/YYYY) | D3: 02/29/2024 | E3: FY24 | F3: FY25 | G3: FY26 | H3: FY27 | I3: FY28 | J3: FY29 | L3: Notes
C4: ASSETS
A5: $ | B5: Million | C5: Cash and cash equivalents | D5: 3002 | E5: 3619 | F5: =E5 -> 3619 | G5: =F5 -> 3619 | H5: =E5 -> 3619 | I5: =E5 -> 3619 | J5: =E5 -> 3619 | L5: Assumption constant before any changes in retained earnings
A6: $ | B6: Million | C6: Trade receivables | D6: 734 | E6: 1056 | F6: =E6 -> 1056 | G6: =F6 -> 1056 | H6: =E6 -> 1056 | I6: =E6 -> 1056 | J6: =E6 -> 1056 | L6: Assumption constant before any changes in retained earnings
A7: $ | B7: Million | C7: Other accounts receivables | F7: =E7 | G7: =F7 | H7: =E7 | I7: =E7 | J7: =E7 | L7: Assumption constant before any changes in retained earnings
A8: $ | B8: Million | C8: Investments | D8: 23 | E8: 21 | F8: =E8 -> 21 | G8: =F8 -> 21 | H8: =E8 -> 21 | I8: =E8 -> 21 | J8: =E8 -> 21 | L8: Assumption constant before any changes in retained earnings
A9: $ | B9: Million | C9: Inventories | D9: 1663 | E9: 1423 | F9: =E9 -> 1423 | G9: =F9 -> 1423 | H9: =E9 -> 1423 | I9: =E9 -> 1423 | J9: =E9 -> 1423 | L9: Assumption constant before any changes in retained earnings
A10: $ | B10: Million | C10: Stockpiles and ore on leach pads | D10: 979 | E10: 761 | F10: =E10 -> 761 | G10: =F10 -> 761 | H10: =E10 -> 761 | I10: =E10 -> 761 | J10: =E10 -> 761 | L10: Assumption constant before any changes in retained earnings
A11: $ | B11: Million | C11: Other receivables | E11: 0 | F11: =E11 -> 0 | G11: =F11 -> 0 | H11: =E11 -> 0 | I11: =E11 -> 0 | J11: =E11 -> 0 | L11: Assumption constant before any changes in retained earnings
A12: $ | B12: Million | C12: Derivative assets | D12: 198 | E12: 0 | F12: =E12 -> 0 | G12: =F12 -> 0 | H12: =E12 -> 0 | I12: =E12 -> 0 | J12: =E12 -> 0 | L12: Assumption constant before any changes in retained earnings
A13: $ | B13: Million | C13: Other current assets | D13: 913 | E13: 786 | F13: =E13 -> 786 | G13: =F13 -> 786 | H13: =E13 -> 786 | I13: =E13 -> 786 | J13: =E13 -> 786 | L13: Assumption constant before any changes in retained earnings
A14: $ | B14: Million | C14: Deferred income tax assets | E14: 0 | F14: =E14 -> 0 | G14: =F14 -> 0 | H14: =E14 -> 0 | I14: =E14 -> 0 | J14: =E14 -> 0 | L14: Assumption constant before any changes in retained earnings
A15: $ | B15: Million | C15: Assets held for sale | E15: 4609 | F15: =E15 -> 4609 | G15: =F15 -> 4609 | H15: =E15 -> 4609 | I15: =E15 -> 4609 | J15: =E15 -> 4609 | L15: Assumption constant before any changes in retained earnings
A16: $ | B16: Million | C16: Current assets | D16: 7512 | E16: =SUM(E5:E15) -> 12275 | F16: =SUM(F5:F15) -> 12275 | G16: =SUM(G5:G15) -> 12275 | H16: =SUM(H5:H15) -> 12275 | I16: =SUM(I5:I15) -> 12275 | J16: =SUM(J5:J15) -> 12275 | L16: Assumption constant before any changes in retained earnings
A17: $ | B17: Million | C17: Property, plant and mine development, net | D17: 37563 | E17: 33547 | F17: =E17 -> 33547 | G17: =F17 -> 33547 | H17: =E17 -> 33547 | I17: =E17 -> 33547 | J17: =E17 -> 33547 | L17: Assumption constant before any changes in retained earnings
A18: $ | B18: Million | C18: Investments | D18: 4143 | E18: 4471 | F18: =E18 -> 4471 | G18: =F18 -> 4471 | H18: =E18 -> 4471 | I18: =E18 -> 4471 | J18: =E18 -> 4471 | L18: Assumption constant before any changes in retained earnings
A19: $ | B19: Million | C19: Stockpiles and ore on leach pads | D19: 1935 | E19: 2266 | F19: =E19 -> 2266 | G19: =F19 -> 2266 | H19: =E19 -> 2266 | I19: =E19 -> 2266 | J19: =E19 -> 2266 | L19: Assumption constant before any changes in retained earnings
A20: $ | B20: Million | C20: Deferred income tax assets | D20: 268 | E20: 124 | F20: =E20 -> 124 | G20: =F20 -> 124 | H20: =E20 -> 124 | I20: =E20 -> 124 | J20: =E20 -> 124 | L20: Assumption constant before any changes in retained earnings
A21: $ | B21: Million | C21: Goodwill | D21: 3001 | E21: 2658 | F21: =E21 -> 2658 | G21: =F21 -> 2658 | H21: =E21 -> 2658 | I21: =E21 -> 2658 | J21: =E21 -> 2658 | L21: Assumption constant before any changes in retained earnings
A22: $ | B22: Million | C22: Derivative assets | D22: 444 | E22: 142 | F22: =E22 -> 142 | G22: =F22 -> 142 | H22: =E22 -> 142 | I22: =E22 -> 142 | J22: =E22 -> 142 | L22: Assumption constant before any changes in retained earnings
A23: $ | B23: Million | C23: Other non-current assets | D23: 640 | E23: 866 | F23: =E23 -> 866 | G23: =F23 -> 866 | H23: =E23 -> 866 | I23: =E23 -> 866 | J23: =E23 -> 866 | L23: Assumption constant before any changes in retained earnings
A24: $ | B24: Million | C24: Non-current assets held for sale
A25: $ | B25: Million | C25: Total assets | D25: 55506 | E25: =SUM(E16:E23) -> 56349 | F25: =SUM(F16:F23) -> 56349 | G25: =SUM(G16:G23) -> 56349 | H25: =SUM(H16:H23) -> 56349 | I25: =SUM(I16:I23) -> 56349 | J25: =SUM(J16:J23) -> 56349 | L25: Assumption constant before any changes in retained earnings
C26: LIABILITIES
A27: $ | B27: Million | C27: Accounts payable | D27: 960 | E27: 843 | F27: =E27 -> 843 | G27: =E27 -> 843 | H27: =E27 -> 843 | I27: =E27 -> 843 | J27: =E27 -> 843 | L27: Constant assumption
A28: $ | B28: Million | C28: Employee-related benefits | D28: 551 | E28: 630 | F28: =E28 -> 630 | G28: =E28 -> 630 | H28: =E28 -> 630 | I28: =E28 -> 630 | J28: =E28 -> 630 | L28: Constant assumption
A29: $ | B29: Million | C29: Income and mining taxes payable | D29: 88 | E29: 381 | F29: =E29 -> 381 | G29: =E29 -> 381 | H29: =E29 -> 381 | I29: =E29 -> 381 | J29: =E29 -> 381 | L29: Constant assumption
A30: $ | B30: Million | C30: Debt | D30: 1923 | E30: 924 | F30: =E30 -> 924 | G30: =E30 -> 924 | H30: =E30 -> 924 | I30: =E30 -> 924 | J30: =E30 -> 924 | L30: Constant assumption
A31: $ | B31: Million | C31: Lease and other financing obligations | D31: 114 | E31: 107 | F31: =E31 -> 107 | G31: =E31 -> 107 | H31: =E31 -> 107 | I31: =E31 -> 107 | J31: =E31 -> 107 | L31: Constant assumption
A32: $ | B32: Million | C32: Other current liabilities | D32: 2362 | E32: 2481 | F32: =E32 -> 2481 | G32: =E32 -> 2481 | H32: =E32 -> 2481 | I32: =E32 -> 2481 | J32: =E32 -> 2481 | L32: Constant assumption
A33: $ | B33: Million | C33: Liabilities held for sale | E33: 2177 | F33: =E33 -> 2177 | G33: =E33 -> 2177 | H33: =E33 -> 2177 | I33: =E33 -> 2177 | J33: =E33 -> 2177 | L33: Constant assumption
A34: $ | B34: Million | C34: Current liabilities | D34: 5998 | E34: =SUM(E27:E33) -> 7543 | F34: =SUM(F27:F33) -> 7543 | G34: =SUM(G27:G33) -> 7543 | H34: =SUM(H27:H33) -> 7543 | I34: =SUM(I27:I33) -> 7543 | J34: =SUM(J27:J33) -> 7543 | L34: Constant assumption
A35: $ | B35: Million | C35: Debt | D35: 6951 | E35: 7552 | F35: =E35 -> 7552 | G35: =E35 -> 7552 | H35: =E35 -> 7552 | I35: =E35 -> 7552 | J35: =E35 -> 7552 | L35: Constant assumption
A36: $ | B36: Million | C36: Lease and other financing obligations | D36: 448 | E36: 389 | F36: =E36 -> 389 | G36: =E36 -> 389 | H36: =E36 -> 389 | I36: =E36 -> 389 | J36: =E36 -> 389 | L36: Constant assumption
A37: $ | B37: Million | C37: Reclamation and remediation liabilities | D37: 8167 | E37: 6394 | F37: =E37 -> 6394 | G37: =E37 -> 6394 | H37: =E37 -> 6394 | I37: =E37 -> 6394 | J37: =E37 -> 6394 | L37: Constant assumption
A38: $ | B38: Million | C38: Deferred income tax liabilities | D38: 2987 | E38: 2820 | F38: =E38 -> 2820 | G38: =E38 -> 2820 | H38: =E38 -> 2820 | I38: =E38 -> 2820 | J38: =E38 -> 2820 | L38: Constant assumption
A39: $ | B39: Million | C39: Employee-related benefits | D39: 655 | E39: 555 | F39: =E39 -> 555 | G39: =E39 -> 555 | H39: =E39 -> 555 | I39: =E39 -> 555 | J39: =E39 -> 555 | L39: Constant assumption
A40: $ | B40: Million | C40: Silver streaming agreement | D40: 779 | E40: 699 | F40: =E40 -> 699 | G40: =E40 -> 699 | H40: =E40 -> 699 | I40: =E40 -> 699 | J40: =E40 -> 699 | L40: Constant assumption
...

Sheet Darft
A1: Newmont 2023 Annual Financial Report
B5: Actual | E5: Projected
B6: 2023 | C6: 2022 | E6: 2025 | F6: 2026 | G6: 2027 | H6: 2028 | I6: 2029
A7: Sales revenues | B7: 11812 | C7: 11915
A8: Cost of Sales | B8: 6699 | C8: 6468
A9: Gross Profit | B9: =B7-B8 -> 5113
A10: Exploration
A11: G&A
A12: Impairment
A13: Other Expense
A14: Operating Profit
A15: Finance Income | D15: investment bonds and equity
A16: Finance Costs
A17: Adjustments
A18: Modifications
A19: Earnings before taxes
A20: Income Tax
A21: Net Income

Sheet Balance Sheet for Q.1C
A1: Currency | B1: Unit | C1: Description | D1: FY 23
C2: Period Ended On (MM/DD/YYYY) | D2: 12/31/2023
C3: Reported Date (MM/DD/YYYY) | D3: 02/29/2024 | E3: FY24 | F3: FY25 | G3: FY26 | H3: FY27 | I3: FY28 | J3: FY29 | L3: Notes
C4: ASSETS
A5: $ | B5: Million | C5: Cash and cash equivalents | D5: 3002 | E5: 3619 | F5: =E5 -> 3619 | G5: =F5 -> 3619 | H5: =G5 -> 3619 | I5: =H5 -> 3619 | J5: =I5 -> 3619 | L5: Assumed constant prior to changes in retained earnings.
A6: $ | B6: Million | C6: Trade receivables | D6: 734 | E6: 1056 | F6: =E6 -> 1056 | G6: =F6 -> 1056 | H6: =G6 -> 1056 | I6: =H6 -> 1056 | J6: =I6 -> 1056
A7: $ | B7: Million | C7: Other accounts receivables | F7: =E7 | G7: =F7 | H7: =G7 | I7: =H7 | J7: =I7
A8: $ | B8: Million | C8: Investments | D8: 23 | E8: 21 | F8: =E8 -> 21 | G8: =F8 -> 21 | H8: =G8 -> 21 | I8: =H8 -> 21 | J8: =I8 -> 21
A9: $ | B9: Million | C9: Inventories | D9: 1663 | E9: 1423 | F9: =E9 -> 1423 | G9: =F9 -> 1423 | H9: =G9 -> 1423 | I9: =H9 -> 1423 | J9: =I9 -> 1423
A10: $ | B10: Million | C10: Stockpiles and ore on leach pads | D10: 979 | E10: 761 | F10: =E10 -> 761 | G10: =F10 -> 761 | H10: =G10 -> 761 | I10: =H10 -> 761 | J10: =I10 -> 761
A11: $ | B11: Million | C11: Other receivables | E11: 0 | F11: =E11 -> 0 | G11: =F11 -> 0 | H11: =G11 -> 0 | I11: =H11 -> 0 | J11: =I11 -> 0
A12: $ | B12: Million | C12: Derivative assets | D12: 198 | E12: 0 | F12: =E12 -> 0 | G12: =F12 -> 0 | H12: =G12 -> 0 | I12: =H12 -> 0 | J12: =I12 -> 0
A13: $ | B13: Million | C13: Other current assets | D13: 913 | E13: 786 | F13: =E13 -> 786 | G13: =F13 -> 786 | H13: =G13 -> 786 | I13: =H13 -> 786 | J13: =I13 -> 786
A14: $ | B14: Million | C14: Deferred income tax assets | E14: 0 | F14: =E14 -> 0 | G14: =F14 -> 0 | H14: =G14 -> 0 | I14: =H14 -> 0 | J14: =I14 -> 0
A15: $ | B15: Million | C15: Assets held for sale | E15: 4609 | F15: =E15 -> 4609 | G15: =F15 -> 4609 | H15: =G15 -> 4609 | I15: =H15 -> 4609 | J15: =I15 -> 4609
A16: $ | B16: Million | C16: Current assets | D16: 7512 | E16: =SUM(E5:E15) -> 12275 | F16: =E16 -> 12275 | G16: =F16 -> 12275 | H16: =G16 -> 12275 | I16: =H16 -> 12275 | J16: =I16 -> 12275
A17: $ | B17: Million | C17: Property, plant and mine development, net | D17: 37563 | E17: 33547 | F17: =E17 -> 33547 | G17: =F17 -> 33547 | H17: =G17 -> 33547 | I17: =H17 -> 33547 | J17: =I17 -> 33547
A18: $ | B18: Million | C18: Investments | D18: 4143 | E18: 4471 | F18: =E18 -> 4471 | G18: =F18 -> 4471 | H18: =G18 -> 4471 | I18: =H18 -> 4471 | J18: =I18 -> 4471
A19: $ | B19: Million | C19: Stockpiles and ore on leach pads | D19: 1935 | E19: 2266 | F19: =E19 -> 2266 | G19: =F19 -> 2266 | H19: =G19 -> 2266 | I19: =H19 -> 2266 | J19: =I19 -> 2266
A20: $ | B20: Million | C20: Deferred income tax assets | D20: 268 | E20: 124 | F20: =E20 -> 124 | G20: =F20 -> 124 | H20: =G20 -> 124 | I20: =H20 -> 124 | J20: =I20 -> 124
A21: $ | B21: Million | C21: Goodwill | D21: 3001 | E21: 2658 | F21: =E21 -> 2658 | G21: =F21 -> 2658 | H21: =G21 -> 2658 | I21: =H21 -> 2658 | J21: =I21 -> 2658
A22: $ | B22: Million | C22: Derivative assets | D22: 444 | E22: 142 | F22: =E22 -> 142 | G22: =F22 -> 142 | H22: =G22 -> 142 | I22: =H22 -> 142 | J22: =I22 -> 142
A23: $ | B23: Million | C23: Other non-current assets | D23: 640 | E23: 866 | F23: =E23 -> 866 | G23: =F23 -> 866 | H23: =G23 -> 866 | I23: =H23 -> 866 | J23: =I23 -> 866
A24: $ | B24: Million | C24: Non-current assets held for sale | F24: =E24 | G24: =F24 | H24: =G24 | I24: =H24 | J24: =I24
A25: $ | B25: Million | C25: Total assets | D25: 55506 | E25: =SUM(E16:E23) -> 56349 | F25: =E25 -> 56349 | G25: =F25 -> 56349 | H25: =G25 -> 56349 | I25: =H25 -> 56349 | J25: =I25 -> 56349
C26: LIABILITIES | F26: =E26 | G26: =F26 | H26: =G26 | I26: =H26 | J26: =I26
A27: $ | B27: Million | C27: Accounts payable | D27: 960 | E27: 843 | F27: =E27 -> 843 | G27: =F27 -> 843 | H27: =G27 -> 843 | I27: =H27 -> 843 | J27: =I27 -> 843 | L27: Constant assumption
A28: $ | B28: Million | C28: Employee-related benefits | D28: 551 | E28: 630 | F28: =E28 -> 630 | G28: =F28 -> 630 | H28: =G28 -> 630 | I28: =H28 -> 630 | J28: =I28 -> 630
A29: $ | B29: Million | C29: Income and mining taxes payable | D29: 88 | E29: 381 | F29: =E29 -> 381 | G29: =F29 -> 381 | H29: =G29 -> 381 | I29: =H29 -> 381 | J29: =I29 -> 381
A30: $ | B30: Million | C30: Debt | D30: 1923 | E30: 924 | F30: =E30 -> 924 | G30: =F30 -> 924 | H30: =G30 -> 924 | I30: =H30 -> 924 | J30: =I30 -> 924
A31: $ | B31: Million | C31: Lease and other financing obligations | D31: 114 | E31: 107 | F31: =E31 -> 107 | G31: =F31 -> 107 | H31: =G31 -> 107 | I31: =H31 -> 107 | J31: =I31 -> 107
A32: $ | B32: Million | C32: Other current liabilities | D32: 2362 | E32: 2481 | F32: =E32 -> 2481 | G32: =F32 -> 2481 | H32: =G32 -> 2481 | I32: =H32 -> 2481 | J32: =I32 -> 2481
A33: $ | B33: Million | C33: Liabilities held for sale | E33: 2177 | F33: =E33 -> 2177 | G33: =F33 -> 2177 | H33: =G33 -> 2177 | I33: =H33 -> 2177 | J33: =I33 -> 2177
A34: $ | B34: Million | C34: Current liabilities | D34: 5998 | E34: =SUM(E27:E33) -> 7543 | F34: =E34 -> 7543 | G34: =F34 -> 7543 | H34: =G34 -> 7543 | I34: =H34 -> 7543 | J34: =I34 -> 7543
A35: $ | B35: Million | C35: Debt | D35: 6951 | E35: 7552 | F35: =E35 -> 7552 | G35: =F35 -> 7552 | H35: =G35 -> 7552 | I35: =H35 -> 7552 | J35: =I35 -> 7552
A36: $ | B36: Million | C36: Lease and other financing obligations | D36: 448 | E36: 389 | F36: =E36 -> 389 | G36: =F36 -> 389 | H36: =G36 -> 389 | I36: =H36 -> 389 | J36: =I36 -> 389
A37: $ | B37: Million | C37: Reclamation and remediation liabilities | D37: 8167 | E37: 6394 | F37: =E37 -> 6394 | G37: =F37 -> 6394 | H37: =G37 -> 6394 | I37: =H37 -> 6394 | J37: =I37 -> 6394
A38: $ | B38: Million | C38: Deferred income tax liabilities | D38: 2987 | E38: 2820 | F38: =E38 -> 2820 | G38: =F38 -> 2820 | H38: =G38 -> 2820 | I38: =H38 -> 2820 | J38: =I38 -> 2820
A39: $ | B39: Million | C39: Employee-related benefits | D39: 655 | E39: 555 | F39: =E39 -> 555 | G39: =F39 -> 555 | H39: =G39 -> 555 | I39: =H39 -> 555 | J39: =I39 -> 555
A40: $ | B40: Million | C40: Silver streaming agreement | D40: 779 | E40: 699 | F40: =E40 -> 699 | G40: =F40 -> 699 | H40: =G40 -> 699 | I40: =H40 -> 699 | J40: =I40 -> 699
...

Sheet Balance Sheet for Q.1D
A1: Currency | B1: Unit | C1: Description | D1: FY 23
C2: Period Ended On (MM/DD/YYYY) | D2: 12/31/2023
C3: Reported Date (MM/DD/YYYY) | D3: 02/29/2024 | E3: FY24 | F3: FY25 | G3: FY26 | H3: FY27 | I3: FY28 | J3: FY29 | L3: Notes
C4: ASSETS
A5: $ | B5: Million | C5: Cash and cash equivalents | D5: 3002 | E5: 3619 | F5: =E5 -> 3619 | G5: =F5 -> 3619 | H5: =G5 -> 3619 | I5: =H5 -> 3619 | J5: =I5 -> 3619 | L5: Assumed constant prior to changes in retained earnings.
A6: $ | B6: Million | C6: Trade receivables | D6: 734 | E6: 1056 | F6: =E6 -> 1056 | G6: =F6 -> 1056 | H6: =G6 -> 1056 | I6: =H6 -> 1056 | J6: =I6 -> 1056
A7: $ | B7: Million | C7: Other accounts receivables | F7: =E7 | G7: =F7 | H7: =G7 | I7: =H7 | J7: =I7
A8: $ | B8: Million | C8: Investments | D8: 23 | E8: 21 | F8: =E8 -> 21 | G8: =F8 -> 21 | H8: =G8 -> 21 | I8: =H8 -> 21 | J8: =I8 -> 21
A9: $ | B9: Million | C9: Inventories | D9: 1663 | E9: 1423 | F9: =E9 -> 1423 | G9: =F9 -> 1423 | H9: =G9 -> 1423 | I9: =H9 -> 1423 | J9: =I9 -> 1423
A10: $ | B10: Million | C10: Stockpiles and ore on leach pads | D10: 979 | E10: 761 | F10: =E10 -> 761 | G10: =F10 -> 761 | H10: =G10 -> 761 | I10: =H10 -> 761 | J10: =I10 -> 761
A11: $ | B11: Million | C11: Other receivables | E11: 0 | F11: =E11 -> 0 | G11: =F11 -> 0 | H11: =G11 -> 0 | I11: =H11 -> 0 | J11: =I11 -> 0
A12: $ | B12: Million | C12: Derivative assets | D12: 198 | E12: 0 | F12: =E12 -> 0 | G12: =F12 -> 0 | H12: =G12 -> 0 | I12: =H12 -> 0 | J12: =I12 -> 0
A13: $ | B13: Million | C13: Other current assets | D13: 913 | E13: 786 | F13: =E13 -> 786 | G13: =F13 -> 786 | H13: =G13 -> 786 | I13: =H13 -> 786 | J13: =I13 -> 786
A14: $ | B14: Million | C14: Deferred income tax assets | E14: 0 | F14: =E14 -> 0 | G14: =F14 -> 0 | H14: =G14 -> 0 | I14: =H14 -> 0 | J14: =I14 -> 0
A15: $ | B15: Million | C15: Assets held for sale | E15: 4609 | F15: =E15 -> 4609 | G15: =F15 -> 4609 | H15: =G15 -> 4609 | I15: =H15 -> 4609 | J15: =I15 -> 4609
A16: $ | B16: Million | C16: Current assets | D16: 7512 | E16: =SUM(E5:E15) -> 12275 | F16: =E16 -> 12275 | G16: =F16 -> 12275 | H16: =G16 -> 12275 | I16: =H16 -> 12275 | J16: =I16 -> 12275
A17: $ | B17: Million | C17: Property, plant and mine development, net | D17: 37563 | E17: 33547 | F17: =E17 -> 33547 | G17: =F17 -> 33547 | H17: =G17 -> 33547 | I17: =H17 -> 33547 | J17: =I17 -> 33547
A18: $ | B18: Million | C18: Investments | D18: 4143 | E18: 4471 | F18: =E18 -> 4471 | G18: =F18 -> 4471 | H18: =G18 -> 4471 | I18: =H18 -> 4471 | J18: =I18 -> 4471
A19: $ | B19: Million | C19: Stockpiles and ore on leach pads | D19: 1935 | E19: 2266 | F19: =E19 -> 2266 | G19: =F19 -> 2266 | H19: =G19 -> 2266 | I19: =H19 -> 2266 | J19: =I19 -> 2266
A20: $ | B20: Million | C20: Deferred income tax assets | D20: 268 | E20: 124 | F20: =E20 -> 124 | G20: =F20 -> 124 | H20: =G20 -> 124 | I20: =H20 -> 124 | J20: =I20 -> 124
A21: $ | B21: Million | C21: Goodwill | D21: 3001 | E21: 2658 | F21: =E21 -> 2658 | G21: =F21 -> 2658 | H21: =G21 -> 2658 | I21: =H21 -> 2658 | J21: =I21 -> 2658
A22: $ | B22: Million | C22: Derivative assets | D22: 444 | E22: 142 | F22: =E22 -> 142 | G22: =F22 -> 142 | H22: =G22 -> 142 | I22: =H22 -> 142 | J22: =I22 -> 142
A23: $ | B23: Million | C23: Other non-current assets | D23: 640 | E23: 866 | F23: =E23 -> 866 | G23: =F23 -> 866 | H23: =G23 -> 866 | I23: =H23 -> 866 | J23: =I23 -> 866
A24: $ | B24: Million | C24: Non-current assets held for sale | F24: =E24 | G24: =F24 | H24: =G24 | I24: =H24 | J24: =I24
A25: $ | B25: Million | C25: Total assets | D25: 55506 | E25: =SUM(E16:E23) -> 56349 | F25: =E25 -> 56349 | G25: =F25 -> 56349 | H25: =G25 -> 56349 | I25: =H25 -> 56349 | J25: =I25 -> 56349
C26: LIABILITIES | F26: =E26 | G26: =F26 | H26: =G26 | I26: =H26 | J26: =I26
A27: $ | B27: Million | C27: Accounts payable | D27: 960 | E27: 843 | F27: =E27 -> 843 | G27: =F27 -> 843 | H27: =G27 -> 843 | I27: =H27 -> 843 | J27: =I27 -> 843 | L27: Constant assumption
A28: $ | B28: Million | C28: Employee-related benefits | D28: 551 | E28: 630 | F28: =E28 -> 630 | G28: =F28 -> 630 | H28: =G28 -> 630 | I28: =H28 -> 630 | J28: =I28 -> 630
A29: $ | B29: Million | C29: Income and mining taxes payable | D29: 88 | E29: 381 | F29: =E29 -> 381 | G29: =F29 -> 381 | H29: =G29 -> 381 | I29: =H29 -> 381 | J29: =I29 -> 381
A30: $ | B30: Million | C30: Debt | D30: 1923 | E30: 924 | F30: =E30 -> 924 | G30: =F30 -> 924 | H30: =G30 -> 924 | I30: =H30 -> 924 | J30: =I30 -> 924
A31: $ | B31: Million | C31: Lease and other financing obligations | D31: 114 | E31: 107 | F31: =E31 -> 107 | G31: =F31 -> 107 | H31: =G31 -> 107 | I31: =H31 -> 107 | J31: =I31 -> 107
A32: $ | B32: Million | C32: Other current liabilities | D32: 2362 | E32: 2481 | F32: =E32 -> 2481 | G32: =F32 -> 2481 | H32: =G32 -> 2481 | I32: =H32 -> 2481 | J32: =I32 -> 2481
A33: $ | B33: Million | C33: Liabilities held for sale | E33: 2177 | F33: =E33 -> 2177 | G33: =F33 -> 2177 | H33: =G33 -> 2177 | I33: =H33 -> 2177 | J33: =I33 -> 2177
A34: $ | B34: Million | C34: Current liabilities | D34: 5998 | E34: =SUM(E27:E33) -> 7543 | F34: =E34 -> 7543 | G34: =F34 -> 7543 | H34: =G34 -> 7543 | I34: =H34 -> 7543 | J34: =I34 -> 7543
A35: $ | B35: Million | C35: Debt | D35: 6951 | E35: 7552 | F35: =E35 -> 7552 | G35: =F35 -> 7552 | H35: =G35 -> 7552 | I35: =H35 -> 7552 | J35: =I35 -> 7552
A36: $ | B36: Million | C36: Lease and other financing obligations | D36: 448 | E36: 389 | F36: =E36 -> 389 | G36: =F36 -> 389 | H36: =G36 -> 389 | I36: =H36 -> 389 | J36: =I36 -> 389
A37: $ | B37: Million | C37: Reclamation and remediation liabilities | D37: 8167 | E37: 6394 | F37: =E37 -> 6394 | G37: =F37 -> 6394 | H37: =G37 -> 6394 | I37: =H37 -> 6394 | J37: =I37 -> 6394
A38: $ | B38: Million | C38: Deferred income tax liabilities | D38: 2987 | E38: 2820 | F38: =E38 -> 2820 | G38: =F38 -> 2820 | H38: =G38 -> 2820 | I38: =H38 -> 2820 | J38: =I38 -> 2820
A39: $ | B39: Million | C39: Employee-related benefits | D39: 655 | E39: 555 | F39: =E39 -> 555 | G39: =F39 -> 555 | H39: =G39 -> 555 | I39: =H39 -> 555 | J39: =I39 -> 555
A40: $ | B40: Million | C40: Silver streaming agreement | D40: 779 | E40: 699 | F40: =E40 -> 699 | G40: =F40 -> 699 | H40: =G40 -> 699 | I40: =H40 -> 699 | J40: =I40 -> 699
...

Sheet Question 2
B1: Question 2
A3: a) | B3: Make changes to the assumptions so as to generate the highest possible temperature increase. The url on your browser will change as you change the assumptions. Submit the url for the highest temperature increase scenario. Write a narrative describe the assumptions and the impacts on primary energy sources, emissions and temperature.
B6: Link: | C6: Highest possible temperature increase
B31: Energy Supply
A32: > | B32: In this scenario, the temperature increases as high as 5.1°C by 2100 as the world continues to subsidize coal, oil, and natural gas, keeping these energy sources affordable and widely available. This leads to their continued use and contributes to higher carbon emissions and rising temperatures. Bioenergy use while seemingly a step toward renewable energy, will also cause the global temperature to rise as converting the biomass into usable energy still releases carbon emissions into the atmosphere.
A33: > | B33: High taxes on nuclear and renewable energy will discourage investment, slowing the transition to clean energy and increasing reliance on fossil fuels. At the same time, the lack of progress in carbon pricing policies weakens incentives for emissions reduction, making it unlikely for industries to move away from carbon-intensive practices. All of these factors will drive up carbon emissions and global temperatures.
A34: > | B34: Without breakthroughs in zero-carbon technology, the world will be left with no other options than to continue the reliance on carbon-intensive energy sources, which further the dependency on high-emission energy sources and exacerbating climate challenges.
B36: Energy Efficiency and Electrification
B37: Insufficient support for energy efficiency and electrification in transportation, buildings, and industry (combined with the lack of progress in shifting towards clean energy) will demand more use of fossil fuels. Combined with the increase in population and economic growth (which means more energy-intensive activity), will lead to higher carbon emissions and a rise in global temperatures.
B39: Carbon dioxide removal and other sources of GHG
B40: No progress in nature-based carbon dioxide removal, such as reforestation and ecosystem restoration, yet increasing deforestation rate, will reduce natural carbon absorption rate. Slow advancements in technological-based carbon dioxide removal will further limit emission offsets. Stagnant improvements and progress in agricultural emissions, along with continued waste and leakage, will add to rising emissions of other greenhouse gas like methane. These factors will increase atmospheric carbon emissions and drive temperature to rise significantly.
A42: b) | B42: Make changes to the assumptions so as to generate the lowest possible temperature increase. Submit the url for this scenario. Write a narrative describe the assumptions and the impacts on primary energy sources, emissions and temperature.
B45: Link: | C45: Lowest possible temperature increase
B69: Energy Supply
A70: > | B70: In this scenario, the temperature increases only by 1.2°C by 2100, way below the temperature increase limit set in the Paris Agreement. This positive outcome is due to a significant reduction in the use of high-emission energy sources such as oil, gas, coal, and bioenergy because of the high taxes imposed on these dirty energy sources that make them less economically viable. At the same time, substantial subsidies for renewable energy and clean technologies accelerate their adoption, making them more cost-competitive and as a result, causing the world to shift toward cleaner alternatives.
A71: > | B71: This is also supported by the breakthroughs in zero-carbon technology which further enhance its efficiency and scalability, and a high carbon price incentivizes industries to cut emissions and adopt low-carbon solutions. These combined factors lead to lower greenhouse gas emissions and a less significant temperature increase compared to the first scenario.
B73: Energy Efficiency and Electrification
B74: Increased energy efficiency and electrification in transportation, buildings, and industry reduce primary energy demand and consumption, leading to lower emissions. Low population growth further reduces energy demand. While low economic growth has drawbacks for the world’s economy, it leads to reduced carbon emissions because of less industrial or economic activity which means low energy use. These factors contribute to the overall smaller carbon emissions and temperature increases.
B76: Carbon dioxide removal and other sources of GHG
A77: > | B77: Significant progress in nature-based carbon dioxide removal reduces emissions as scenario like reforestation and lower deforestation rates increase carbon absorption. Advancement in tech-based carbon removal further decrease emissions by capturing and storing carbon more efficiently. This will reduce carbon emissions in the atmosphere and reduce the risk of world’s temperature increase.
A78: > | B78: Improvements in agricultural practices (for example, through regenerative agriculture practices) will lead to lower methane emissions, while reductions in waste and leakage minimize unnecessary greenhouse gas output from energy use and methane release from landfills and supply chains. These efforts collectively decrease emissions and a lower temperature increase.
A80: c) | B80: Make changes to the assumptions so as to generate what you consider to be a plausibly good outcome. Submit the url for this scenario. Write a narrative describe the assumptions and the impacts on primary energy sources, emissions and temperature.
B83: Link: | C83: Plausible good outcome
B108: Energy Supply
A109: > | B109: The scenario is based on assumptions on the current world’s progress in climate change. Note that these are “plausibly good outcomes” scenarios and might differ from the actual condition in the world (considering aspects such as economics and politics).
A110: > | B110: In this scenario, the world experiences a 1.9°C temperature increase by 2100. Moderate taxation on coal, oil, and gas reduces their use but does not eliminate reliance on fossil fuels. Bioenergy taxation remains unchanged, maintaining its current role in the energy mix. However, high subsidies for renewables and increased support for nuclear power encourage a shift toward cleaner energy sources.
A111: > | B111: A moderate rate of breakthroughs in zero-carbon technology improves efficiency and adoption, but not rapidly enough to fully replace fossil fuels. Additionally, a rising carbon price incentivizes emission reductions, though its impact is (again) still limited by continued fossil fuel use. These conditions lead to lower emissions than in high-emission scenarios but not enough to keep temperature rise below 1.5°C.
B113: Energy Efficiency and Electrification
B114: This scenario supports efforts to improve energy efficiency and electrification in transportation, buildings, and industry. This energy efficiency will lower primary energy consumption required for these sector. Eventhough a low population growth slows the increase of energy consumption, high economic growth will drive industrial or economic activity and still increase energy use. However, advancements in clean energy and efficiency measures help offset some of the emissions from increased economic activity.
B116: Carbon dioxide removal and other sources of GHG
B117: This scenario is similar to the 1.2°C temperature increase scenario in terms of nature-based and technological carbon dioxide removal, reduced agricultural emissions, lower waste and leakage, and decreased deforestation. However, the impact is more moderate, with only medium growth in carbon dioxide removal efforts and a medium reduction in agricultural emissions, waste leakage, and deforestation rates. As a result, while emissions decline, they do so at a slower pace, leading to a higher overall temperature increase of 1.9°C by 2100 instead of 1.2°C. The improvements still contribute to lowering net emissions, but not enough to achieve the lowest warming scenario.
